<?xml version="1.0"?>
<robot xmlns:xacro="http://www.ros.org/wiki/xacro">
<xacro:macro name="joint_model" params="prefix">

  <joint name="base_joint" type="fixed">
    <parent link="world"/>
    <child link="base_link"/>
    <origin xyz="0 0 0" rpy="0 0 0"/>
  </joint>

  <xacro:property name="stator_size" value="0.102 0.102 0.102" />
  <link name="${prefix}_stator_link">
    <visual>
      <geometry>
        <box size="${stator_size}"/>
      </geometry>
      <material name="black">
        <color rgba="0 0 0 1"/>
      </material>
    </visual>
  </link>

  <joint name="${prefix}_stator_joint" type="fixed">
    <parent link="base_link"/>
    <child link="${prefix}_stator_link"/>
    <origin xyz="0 0 0.051" rpy="0 0 0"/>
  </joint>

  <xacro:property name="radius" value="0.025" />
  <xacro:property name="length" value="0.01" />
  <link name="${prefix}_rotor_link">
    <visual>
      <geometry>
        <cylinder radius="${radius}" length="${length}"/>
      </geometry>
      <material name="red">
        <color rgba="1 0 0 1"/>
      </material>
    </visual>
  </link>

  <joint name="${prefix}_angle" type="revolute">
    <parent link="${prefix}_stator_link"/>
    <child link="${prefix}_rotor_link"/>
    <origin xyz="0 0 0.051" rpy="0 0 0"/>
    <axis xyz="0 0 1"/>
    <limit effort="1" velocity="1" lower="-3.14" upper="3.14"/>
  </joint>

  <xacro:property name="angle_size" value="0.025 0.002 0.002" />
  <link name="${prefix}_angle_link">
    <visual>
      <geometry>
        <box size="${angle_size}"/>
      </geometry>
      <origin xyz="0.0125 0 0.006" rpy="0 0 0"/>
      <material name="white">
        <color rgba="1 1 1 1"/>
      </material>
    </visual>
  </link>

  <joint name="indicator" type="fixed">
    <parent link="${prefix}_rotor_link"/>
    <child link="${prefix}_angle_link"/>
    <origin xyz="0 0 0" rpy="0 0 0"/>
  </joint>

</xacro:macro>
</robot>